{
  "class": "vulnerability",
  "id": "oval:com.ubuntu.xenial:def:2023335950000000",
  "version": "1",
  "metadata": {
    "Title": "CVE-2023-33595 on Ubuntu 16.04 FIPS Compliant (xenial) - medium.",
    "Description": "CPython v3.12.0 alpha 7 was discovered to contain a heap use-after-free via the function ascii_decode at /Objects/unicodeobject.c.",
    "affected": {
      "family": "unix",
      "Platform": "Ubuntu 16.04 FIPS Compliant"
    },
    "reference": {
      "source": "CVE",
      "ref_id": "CVE-2023-33595",
      "ref_url": "https://cve.mitre.org/cgi-bin/cvename.cgi?name=CVE-2023-33595"
    },
    "advisory": {
      "Severity": "Medium",
      "Rights": "Copyright (C) 2023 Canonical Ltd.",
      "PublicDate": "2023-06-07 20:15:00 UTC",
      "Bug": null,
      "cve": {
        "text": "CVE-2023-33595",
        "href": "https://ubuntu.com/security/CVE-2023-33595",
        "public": "20230607",
        "cvss_score": "5.5",
        "cvss_vector": "CVSS:3.1/AV:L/AC:L/PR:N/UI:R/S:U/C:N/I:N/A:H"
      },
      "PublicDateAtUsn": "",
      "AssignedTo": "",
      "DiscoveredBy": "",
      "Crd": "",
      "Ref": null
    }
  },
  "notes": {
    "Note": "alexmurray> This vulnerability was introduced in upstream commit 1ef61cf71a218c71860ff6aecf0fd51edb8b65dc and the fix was also committed upstream in commit d5a97074d24cd14cb2a35a2b1ad3074863cde264 - both of these were part of the 3.12.0b1 release, so no versions of python3.12 in ubuntu were affected (also no other python3.x versions are affected as the original vulnerable commit was only released during the development of python 3.12)"
  },
  "criteria": {
    "criterias": [
      {
        "operator": "OR",
        "criterions": [
          {
            "test_ref": "oval:com.ubuntu.xenial:tst:2015201070000000",
            "comment": "python2.7: while related to the CVE in some way, a decision has been made to ignore this issue (note: 'end of standard support')."
          },
          {
            "test_ref": "oval:com.ubuntu.xenial:tst:2015201070000010",
            "comment": "python3.5: while related to the CVE in some way, a decision has been made to ignore this issue (note: 'end of standard support')."
          }
        ]
      }
    ]
  }
}
