{
	"class": "patch",
	"id": "oval:com.ubuntu.xenial:def:46641000000",
	"version": "1",
	"metadata": {
		"title": "USN-4664-1 -- Aptdaemon vulnerabilities",
		"description": "Kevin Backhouse discovered that Aptdaemon incorrectly handled certain properties. A local attacker could use this issue to test for the presence of local files. (CVE-2020-16128)  Kevin Backhouse discovered that Aptdaemon incorrectly handled permission checks. A local attacker could possibly use this issue to cause a denial of service. (CVE-2020-27349)  Update Instructions:  Run `sudo pro fix USN-4664-1` to fix the vulnerability. The problem can be corrected by updating your system to the following package versions:  python3-aptdaemon.gtk3widgets - 1.1.1+bzr982-0ubuntu14.5 python-aptdaemon - 1.1.1+bzr982-0ubuntu14.5 aptdaemon-data - 1.1.1+bzr982-0ubuntu14.5 python3-aptdaemon.test - 1.1.1+bzr982-0ubuntu14.5 aptdaemon - 1.1.1+bzr982-0ubuntu14.5 python3-aptdaemon.pkcompat - 1.1.1+bzr982-0ubuntu14.5 python-aptdaemon.gtk3widgets - 1.1.1+bzr982-0ubuntu14.5 python3-aptdaemon - 1.1.1+bzr982-0ubuntu14.5 No subscription required",
		"affected": {
			"family": "unix",
			"platform": "Ubuntu 16.04 LTS"
		},
		"reference": [
			{
				"source": "USN",
				"ref_id": "USN-4664-1",
				"ref_url": "https://ubuntu.com/security/notices/USN-4664-1"
			}
		],
		"advisory": {
			"from": "security@ubuntu.com",
			"severity": "None",
			"issued": {
				"date": "2020-12-08"
			}
		}
	},
	"criteria": {
		"criterias": [
			{
				"operator": "OR",
				"criterions": [
					{
						"test_ref": "oval:com.ubuntu.xenial:tst:466410000000",
						"comment": "Long Term Support"
					}
				]
			}
		]
	}
}
