{
	"class": "vulnerability",
	"id": "oval:com.ubuntu.impish:def:202141890000000",
	"version": "1",
	"metadata": {
		"Title": "CVE-2021-4189 on Ubuntu 21.10 (impish) - medium.",
		"Description": "[ftplib should not use the host from the PASV response]\n\nUpdate Instructions:\n\nRun `sudo ua fix CVE-2021-4189` to fix the vulnerability. The problem can be corrected\nby updating your system to the following package versions:\n\nidle-python3.10 - 3.10.0-2\nlibpython3.10 - 3.10.0-2\nlibpython3.10-minimal - 3.10.0-2\nlibpython3.10-stdlib - 3.10.0-2\nlibpython3.10-testsuite - 3.10.0-2\npython3.10 - 3.10.0-2\npython3.10-examples - 3.10.0-2\npython3.10-full - 3.10.0-2\npython3.10-minimal - 3.10.0-2\npython3.10-venv - 3.10.0-2\nNo subscription required\n\nidle-python3.9 - 3.9.7-2build1\nlibpython3.9 - 3.9.7-2build1\nlibpython3.9-minimal - 3.9.7-2build1\nlibpython3.9-stdlib - 3.9.7-2build1\nlibpython3.9-testsuite - 3.9.7-2build1\npython3.9 - 3.9.7-2build1\npython3.9-examples - 3.9.7-2build1\npython3.9-full - 3.9.7-2build1\npython3.9-minimal - 3.9.7-2build1\npython3.9-venv - 3.9.7-2build1\nNo subscription required",
		"affected": {
			"family": "unix",
			"Platform": "Ubuntu 21.10"
		},
		"reference": {
			"source": "CVE",
			"ref_id": "CVE-2021-4189",
			"ref_url": "https://cve.mitre.org/cgi-bin/cvename.cgi?name=CVE-2021-4189"
		},
		"advisory": {
			"Severity": "Medium",
			"Rights": "Copyright (C) 2021 Canonical Ltd.",
			"PublicDate": "2021-12-31 00:00:00 UTC",
			"Bug": null,
			"cve": {},
			"PublicDateAtUsn": "2021-12-31 00:00:00 UTC",
			"AssignedTo": "leosilva",
			"DiscoveredBy": "",
			"Crd": "",
			"Ref": [
				"https://ubuntu.com/security/CVE-2021-4189",
				"https://bugs.python.org/issue43285",
				"https://github.com/python/cpython/commit/0ab152c6b5d95caa2dc1a30fa96e10258b5f188e (master)",
				"https://github.com/python/cpython/commit/7dcb4baa4f0fde3aef5122a8e9f6a41853ec9335 (v3.9.3)",
				"https://github.com/python/cpython/commit/79373951b3eab585d42e0f0ab83718cbe1d0ee33 (v3.7.11)",
				"https://github.com/python/cpython/commit/4134f154ae2f621f25c5d698cc0f1748035a1b88 (v3.6.14)",
				"https://bugzilla.redhat.com/show_bug.cgi?id=2036020",
				"https://ubuntu.com/security/notices/USN-5342-1"
			]
		}
	},
	"notes": {
		"Note": ""
	},
	"criteria": {
		"criterias": [
			{
				"operator": "OR",
				"criterions": [
					{
						"test_ref": "oval:com.ubuntu.impish:tst:2017182070000000",
						"comment": "python2.7 package in impish is affected and may need fixing."
					},
					{
						"test_ref": "oval:com.ubuntu.impish:tst:202141890000010",
						"comment": "python3.10 package in impish, is related to the CVE in some way and has been fixed (note: '3.10.0-2')."
					},
					{
						"test_ref": "oval:com.ubuntu.impish:tst:202141890000020",
						"comment": "python3.9 package in impish, is related to the CVE in some way and has been fixed (note: '3.9.7-2build1')."
					}
				]
			}
		]
	}
}
